<!-- 
1.创建底盘link
2.创建摄像头link
3.通过joint关联底盘与摄像头
-->

<robot name="demo03_joint">
    <!-- 抽取颜色 -->
    <material name="yellow">
        <color rgba="0.8 0.8 0 0.8" />
    </material>
    <material name="red">
        <color rgba="0.8 0.1 0.1 0.8" />
    </material>
    <link name="base_link">
        <visual>
            <geometry>
                <box size="0.5 0.1 0.3"/>
            </geometry>
            <origin xyz="0 0 0" rpy="0 0 0"/>
            <material name="yellow"/>
        </visual>
    </link>
    <!-- 创建摄像头link -->
    <link name="camera">
        <visual>
            <geometry>
                <box size="0.02 0.05 0.05"/>
            </geometry>
            <material name="red"/>
        </visual>
    </link>
    
    <!-- 通过joint关联底盘和摄像头 -->
    <joint name="cameraTobase_link" type="continuous">
        <parent link="base_link"/>
        <child link="camera"/>
        <!-- 设置平移量和旋转度 -->
        <origin xyz="0.2 0.0 0.05"/>
        <!-- 沿哪个坐标轴旋转 -->
        <axis xyz="0 0 1"/>
    </joint>
</robot>
